Workbook

Sheet Valuation
A1: Department | B1: Items | C1: Units valued | D1: Value at cost
A2: Perennials | B2: =COUNTIF(Items!$C$2:$C$59,A2) | C2: =SUMIF(Items!$C$2:$C$59,A2,Items!$E$2:$E$59) | D2: =SUMIF(Items!$C$2:$C$59,A2,Items!$G$2:$G$59)
A3: Shrubs | B3: =COUNTIF(Items!$C$2:$C$59,A3) | C3: =SUMIF(Items!$C$2:$C$59,A3,Items!$E$2:$E$59) | D3: =SUMIF(Items!$C$2:$C$59,A3,Items!$G$2:$G$59)
A4: Trees | B4: =COUNTIF(Items!$C$2:$C$59,A4) | C4: =SUMIF(Items!$C$2:$C$59,A4,Items!$E$2:$E$59) | D4: =SUMIF(Items!$C$2:$C$59,A4,Items!$G$2:$G$59)
A5: Houseplants | B5: =COUNTIF(Items!$C$2:$C$59,A5) | C5: =SUMIF(Items!$C$2:$C$59,A5,Items!$E$2:$E$59) | D5: =SUMIF(Items!$C$2:$C$59,A5,Items!$G$2:$G$59)
A6: Pots & Planters | B6: =COUNTIF(Items!$C$2:$C$59,A6) | C6: =SUMIF(Items!$C$2:$C$59,A6,Items!$E$2:$E$59) | D6: =SUMIF(Items!$C$2:$C$59,A6,Items!$G$2:$G$59)
A7: Soil & Mulch | B7: =COUNTIF(Items!$C$2:$C$59,A7) | C7: =SUMIF(Items!$C$2:$C$59,A7,Items!$E$2:$E$59) | D7: =SUMIF(Items!$C$2:$C$59,A7,Items!$G$2:$G$59)
A8: Tools | B8: =COUNTIF(Items!$C$2:$C$59,A8) | C8: =SUMIF(Items!$C$2:$C$59,A8,Items!$E$2:$E$59) | D8: =SUMIF(Items!$C$2:$C$59,A8,Items!$G$2:$G$59)
A9: Total stock value | B9: =SUM(B2:B8) | C9: =SUM(C2:C8) | D9: =SUM(D2:D8)
A11: Items with no cost on file (listed on Items, left out of the totals)
A12: HOU-0849 | B12: Calathea 6 in | C12: Houseplants | D12: No cost on file - chase with purchasing
A13: PER-0647 | B13: Salvia 'May Night' 1 gal | C13: Perennials | D13: No cost on file - chase with purchasing
A14: PER-0769 | B14: Sedum 'Autumn Joy' 1 gal | C14: Perennials | D14: No cost on file - chase with purchasing
A15: TOL-0119 | B15: Felco F-2 pruner | C15: Tools | D15: No cost on file - chase with purchasing
A16: TRE-0502 | B16: Dwarf Alberta Spruce 5 gal | C16: Trees | D16: No cost on file - chase with purchasing
A18: Negative on-hand counts are valued at zero. Cost is the most recent receipt on the purchasing sheet.

Sheet Items
A1: SKU | B1: Item | C1: Department | D1: On hand | E1: Units valued | F1: Latest cost | G1: Value | H1: Flag
A2: PER-0039 | B2: Echinacea 'Magnus' 1 gal | C2: Perennials | D2: 59 | E2: =MAX(D2,0) | F2: 3.84 | G2: =IF(F2="",0,ROUND(E2*F2,2)) | H2: =IF(F2="","No cost on file - not valued","")
A3: PER-0271 | B3: Hosta 'Patriot' 2 gal | C3: Perennials | D3: 31 | E3: =MAX(D3,0) | F3: 7.52 | G3: =IF(F3="",0,ROUND(E3*F3,2)) | H3: =IF(F3="","No cost on file - not valued","")
A4: PER-0377 | B4: Black-eyed Susan 1 gal | C4: Perennials | D4: 20 | E4: =MAX(D4,0) | F4: 3.37 | G4: =IF(F4="",0,ROUND(E4*F4,2)) | H4: =IF(F4="","No cost on file - not valued","")
A5: PER-0552 | B5: Lavender 'Hidcote' 1 gal | C5: Perennials | D5: 60 | E5: =MAX(D5,0) | F5: 4.57 | G5: =IF(F5="",0,ROUND(E5*F5,2)) | H5: =IF(F5="","No cost on file - not valued","")
A6: PER-0647 | B6: Salvia 'May Night' 1 gal | C6: Perennials | D6: 48 | E6: =MAX(D6,0) | G6: =IF(F6="",0,ROUND(E6*F6,2)) | H6: =IF(F6="","No cost on file - not valued","")
A7: PER-0677 | B7: Coral Bells 1 gal | C7: Perennials | D7: 73 | E7: =MAX(D7,0) | F7: 5.52 | G7: =IF(F7="",0,ROUND(E7*F7,2)) | H7: =IF(F7="","No cost on file - not valued","")
A8: PER-0717 | B8: Daylily 'Stella de Oro' 1 gal | C8: Perennials | D8: 93 | E8: =MAX(D8,0) | F8: 3.22 | G8: =IF(F8="",0,ROUND(E8*F8,2)) | H8: =IF(F8="","No cost on file - not valued","")
A9: PER-0767 | B9: Russian Sage 2 gal | C9: Perennials | D9: 35 | E9: =MAX(D9,0) | F9: 7.22 | G9: =IF(F9="",0,ROUND(E9*F9,2)) | H9: =IF(F9="","No cost on file - not valued","")
A10: PER-0769 | B10: Sedum 'Autumn Joy' 1 gal | C10: Perennials | D10: 98 | E10: =MAX(D10,0) | G10: =IF(F10="",0,ROUND(E10*F10,2)) | H10: =IF(F10="","No cost on file - not valued","")
A11: PER-0824 | B11: Hellebore 2 gal | C11: Perennials | D11: 97 | E11: =MAX(D11,0) | F11: 10.41 | G11: =IF(F11="",0,ROUND(E11*F11,2)) | H11: =IF(F11="","No cost on file - not valued","")
A12: PER-0870 | B12: Catmint 'Walker's Low' 1 gal | C12: Perennials | D12: 17 | E12: =MAX(D12,0) | F12: 4.04 | G12: =IF(F12="",0,ROUND(E12*F12,2)) | H12: =IF(F12="","No cost on file - not valued","")
A13: PER-0871 | B13: Astilbe 1 gal | C13: Perennials | D13: 56 | E13: =MAX(D13,0) | F13: 4.4 | G13: =IF(F13="",0,ROUND(E13*F13,2)) | H13: =IF(F13="","No cost on file - not valued","")
A14: SHR-0011 | B14: Hydrangea 'Limelight' 3 gal | C14: Shrubs | D14: 69 | E14: =MAX(D14,0) | F14: 19.28 | G14: =IF(F14="",0,ROUND(E14*F14,2)) | H14: =IF(F14="","No cost on file - not valued","")
A15: SHR-0015 | B15: Boxwood 'Green Velvet' 3 gal | C15: Shrubs | D15: 80 | E15: =MAX(D15,0) | F15: 16.35 | G15: =IF(F15="",0,ROUND(E15*F15,2)) | H15: =IF(F15="","No cost on file - not valued","")
A16: SHR-0179 | B16: Lilac 5 gal | C16: Shrubs | D16: 88 | E16: =MAX(D16,0) | F16: 23.58 | G16: =IF(F16="",0,ROUND(E16*F16,2)) | H16: =IF(F16="","No cost on file - not valued","")
A17: SHR-0180 | B17: Spirea 'Goldflame' 2 gal | C17: Shrubs | D17: 49 | E17: =MAX(D17,0) | F17: 9.5 | G17: =IF(F17="",0,ROUND(E17*F17,2)) | H17: =IF(F17="","No cost on file - not valued","")
A18: SHR-0213 | B18: Ninebark 'Diabolo' 3 gal | C18: Shrubs | D18: 46 | E18: =MAX(D18,0) | F18: 16.21 | G18: =IF(F18="",0,ROUND(E18*F18,2)) | H18: =IF(F18="","No cost on file - not valued","")
A19: SHR-0224 | B19: Azalea 'Encore' 3 gal | C19: Shrubs | D19: -8 | E19: =MAX(D19,0) | F19: 21.88 | G19: =IF(F19="",0,ROUND(E19*F19,2)) | H19: =IF(F19="","No cost on file - not valued","")
A20: SHR-0230 | B20: Rhododendron 5 gal | C20: Shrubs | D20: 42 | E20: =MAX(D20,0) | F20: 30.04 | G20: =IF(F20="",0,ROUND(E20*F20,2)) | H20: =IF(F20="","No cost on file - not valued","")
A21: SHR-0306 | B21: Viburnum 5 gal | C21: Shrubs | D21: 77 | E21: =MAX(D21,0) | F21: 21.94 | G21: =IF(F21="",0,ROUND(E21*F21,2)) | H21: =IF(F21="","No cost on file - not valued","")
A22: SHR-0331 | B22: Arborvitae 'Emerald Green' 5 gal | C22: Shrubs | D22: -9 | E22: =MAX(D22,0) | F22: 23.31 | G22: =IF(F22="",0,ROUND(E22*F22,2)) | H22: =IF(F22="","No cost on file - not valued","")
... A28: TRE-0493 | B28: Honeycrisp Apple 5 gal | C28: Trees | D28: 53 | E28: =MAX(D28,0) | F28: 44.22 | G28: =IF(F28="",0,ROUND(E28*F28,2)) | H28: =IF(F28="","No cost on file - not valued","")
A29: TRE-0502 | B29: Dwarf Alberta Spruce 5 gal | C29: Trees | D29: 74 | E29: =MAX(D29,0) | G29: =IF(F29="",0,ROUND(E29*F29,2)) | H29: =IF(F29="","No cost on file - not valued","")
A30: TRE-0723 | B30: Kousa Dogwood 15 gal | C30: Trees | D30: 14 | E30: =MAX(D30,0) | F30: 175.45 | G30: =IF(F30="",0,ROUND(E30*F30,2)) | H30: =IF(F30="","No cost on file - not valued","")
A31: TRE-0731 | B31: Sugar Maple B&B 3 in | C31: Trees | D31: 5 | E31: =MAX(D31,0) | F31: 1281.47 | G31: =IF(F31="",0,ROUND(E31*F31,2)) | H31: =IF(F31="","No cost on file - not valued","")
A32: TRE-0848 | B32: Weeping Cherry 15 gal | C32: Trees | D32: 6 | E32: =MAX(D32,0) | F32: 203.9 | G32: =IF(F32="",0,ROUND(E32*F32,2)) | H32: =IF(F32="","No cost on file - not valued","")
A33: HOU-0261 | B33: Monstera 10 in | C33: Houseplants | D33: 99 | E33: =MAX(D33,0) | F33: 23.97 | G33: =IF(F33="",0,ROUND(E33*F33,2)) | H33: =IF(F33="","No cost on file - not valued","")
A34: HOU-0266 | B34: Fiddle Leaf Fig 14 in | C34: Houseplants | D34: 75 | E34: =MAX(D34,0) | F34: 46.06 | G34: =IF(F34="",0,ROUND(E34*F34,2)) | H34: =IF(F34="","No cost on file - not valued","")
A35: HOU-0362 | B35: Snake Plant 6 in | C35: Houseplants | D35: 102 | E35: =MAX(D35,0) | F35: 7.92 | G35: =IF(F35="",0,ROUND(E35*F35,2)) | H35: =IF(F35="","No cost on file - not valued","")
A36: HOU-0373 | B36: Pothos 6 in hanging | C36: Houseplants | D36: 37 | E36: =MAX(D36,0) | F36: 6.84 | G36: =IF(F36="",0,ROUND(E36*F36,2)) | H36: =IF(F36="","No cost on file - not valued","")
A37: HOU-0483 | B37: ZZ Plant 8 in | C37: Houseplants | D37: 11 | E37: =MAX(D37,0) | F37: 13.87 | G37: =IF(F37="",0,ROUND(E37*F37,2)) | H37: =IF(F37="","No cost on file - not valued","")
A38: HOU-0534 | B38: Peace Lily 8 in | C38: Houseplants | D38: 65 | E38: =MAX(D38,0) | F38: 10.67 | G38: =IF(F38="",0,ROUND(E38*F38,2)) | H38: =IF(F38="","No cost on file - not valued","")
A39: HOU-0547 | B39: Bird of Paradise 14 in | C39: Houseplants | D39: -4 | E39: =MAX(D39,0) | F39: 50.85 | G39: =IF(F39="",0,ROUND(E39*F39,2)) | H39: =IF(F39="","No cost on file - not valued","")
A40: HOU-0849 | B40: Calathea 6 in | C40: Houseplants | D40: 89 | E40: =MAX(D40,0) | G40: =IF(F40="",0,ROUND(E40*F40,2)) | H40: =IF(F40="","No cost on file - not valued","")
A41: POT-0090 | B41: Glazed pot 14 in cobalt | C41: Pots & Planters | D41: 80 | E41: =MAX(D41,0) | F41: 22.11 | G41: =IF(F41="",0,ROUND(E41*F41,2)) | H41: =IF(F41="","No cost on file - not valued","")
A42: POT-0191 | B42: Terracotta pot 10 in | C42: Pots & Planters | D42: 88 | E42: =MAX(D42,0) | F42: 4.8 | G42: =IF(F42="",0,ROUND(E42*F42,2)) | H42: =IF(F42="","No cost on file - not valued","")
A43: POT-0323 | B43: Fiberglass planter 24 in | C43: Pots & Planters | D43: 61 | E43: =MAX(D43,0) | F43: 65.34 | G43: =IF(F43="",0,ROUND(E43*F43,2)) | H43: =IF(F43="","No cost on file - not valued","")
A44: POT-0329 | B44: Self-watering planter 12 in | C44: Pots & Planters | D44: 6 | E44: =MAX(D44,0) | F44: 16.86 | G44: =IF(F44="",0,ROUND(E44*F44,2)) | H44: =IF(F44="","No cost on file - not valued","")
A45: POT-0334 | B45: Coco liner hanging basket 14 in | C45: Pots & Planters | D45: 76 | E45: =MAX(D45,0) | F45: 8.34 | G45: =IF(F45="",0,ROUND(E45*F45,2)) | H45: =IF(F45="","No cost on file - not valued","")
...
