Workbook

Sheet Data
A1: shipment_id | B1: hub | C1: promised_window_local | D1: last_piece_local | E1: window_end_local | F1: on_time | G1: late_reason
A2: SHP-60001 | B2: Portland | C2: 2026-08-12 All day | D2: 2026-08-12 08:27 | E2: 2026-08-12 17:00 | F2: 1
A3: SHP-60002 | B3: Portland | C3: 2026-08-24 13:00-15:00 | D3: 2026-08-24 14:51 | E3: 2026-08-24 15:00 | F3: 1
A4: SHP-60003 | B4: Portland | C4: 2026-08-25 All day | D4: 2026-08-25 17:34 | E4: 2026-08-25 17:00 | F4: 0 | G4: Route volume
A5: SHP-60004 | B5: Portland | C5: 2026-08-13 AM | D5: 2026-08-13 10:01 | E5: 2026-08-13 12:00 | F5: 1
A6: SHP-60005 | B6: Portland | C6: 2026-08-11 All day | D6: 2026-08-11 12:50 | E6: 2026-08-11 17:00 | F6: 1
A7: SHP-60006 | B7: Portland | C7: 2026-08-14 13:00-15:00 | D7: 2026-08-14 13:47 | E7: 2026-08-14 15:00 | F7: 1
A8: SHP-60008 | B8: Portland | C8: 2026-08-15 08:00-10:00 | D8: 2026-08-15 09:06 | E8: 2026-08-15 10:00 | F8: 1
A9: SHP-60009 | B9: Portland | C9: 2026-08-03 AM | D9: 2026-08-03 11:44 | E9: 2026-08-03 12:00 | F9: 1
A10: SHP-60010 | B10: Portland | C10: 2026-08-08 08:00-10:00 | D10: 2026-08-08 13:13 | E10: 2026-08-08 10:00 | F10: 0 | G10: Customer
A11: SHP-60011 | B11: Portland | C11: 2026-08-15 13:00-15:00 | D11: 2026-08-15 14:10 | E11: 2026-08-15 15:00 | F11: 1
A12: SHP-60012 | B12: Portland | C12: 2026-08-15 AM | D12: 2026-08-15 09:45 | E12: 2026-08-15 12:00 | F12: 1
A13: SHP-60014 | B13: Portland | C13: 2026-08-25 08:00-10:00 | D13: 2026-08-25 09:50 | E13: 2026-08-25 10:00 | F13: 1
A14: SHP-60015 | B14: Portland | C14: 2026-08-18 All day | D14: 2026-08-18 08:31 | E14: 2026-08-18 17:00 | F14: 1
A15: SHP-60016 | B15: Portland | C15: 2026-08-27 All day | D15: 2026-08-27 15:54 | E15: 2026-08-27 17:00 | F15: 1
A16: SHP-60017 | B16: Portland | C16: 2026-08-13 13:00-15:00 | D16: 2026-08-13 14:30 | E16: 2026-08-13 15:00 | F16: 1
A17: SHP-60018 | B17: Portland | C17: 2026-08-28 AM | D17: 2026-08-28 10:19 | E17: 2026-08-28 12:00 | F17: 1
A18: SHP-60019 | B18: Portland | C18: 2026-08-20 PM | D18: 2026-08-20 13:26 | E18: 2026-08-20 17:00 | F18: 1
A19: SHP-60020 | B19: Portland | C19: 2026-08-03 PM | D19: 2026-08-03 13:56 | E19: 2026-08-03 17:00 | F19: 1
A20: SHP-60021 | B20: Portland | C20: 2026-08-03 08:00-10:00 | D20: 2026-08-03 09:44 | E20: 2026-08-03 10:00 | F20: 1
A21: SHP-60022 | B21: Portland | C21: 2026-08-24 AM | D21: 2026-08-24 11:08 | E21: 2026-08-24 12:00 | F21: 1
A22: SHP-60024 | B22: Portland | C22: 2026-08-11 08:00-10:00 | D22: 2026-08-11 12:09 | E22: 2026-08-11 10:00 | F22: 0 | G22: Customer
A23: SHP-60025 | B23: Portland | C23: 2026-08-18 AM | D23: 2026-08-18 09:24 | E23: 2026-08-18 12:00 | F23: 1
A24: SHP-60026 | B24: Portland | C24: 2026-08-03 AM | D24: 2026-08-03 11:53 | E24: 2026-08-03 12:00 | F24: 1
A25: SHP-60027 | B25: Portland | C25: 2026-08-11 AM | D25: 2026-08-11 11:10 | E25: 2026-08-11 12:00 | F25: 1
A26: SHP-60028 | B26: Portland | C26: 2026-08-06 08:00-10:00 | D26: 2026-08-06 09:33 | E26: 2026-08-06 10:00 | F26: 1
A27: SHP-60029 | B27: Portland | C27: 2026-08-03 08:00-10:00 | D27: 2026-08-03 09:05 | E27: 2026-08-03 10:00 | F27: 1
A28: SHP-60030 | B28: Portland | C28: 2026-08-24 PM | D28: 2026-08-24 15:28 | E28: 2026-08-24 17:00 | F28: 1
A29: SHP-60031 | B29: Portland | C29: 2026-08-14 08:00-10:00 | D29: 2026-08-14 08:19 | E29: 2026-08-14 10:00 | F29: 1
A30: SHP-60032 | B30: Portland | C30: 2026-08-23 All day | D30: 2026-08-23 16:49 | E30: 2026-08-23 17:00 | F30: 1
A31: SHP-60033 | B31: Portland | C31: 2026-08-14 13:00-15:00 | D31: 2026-08-14 14:29 | E31: 2026-08-14 15:00 | F31: 1
A32: SHP-60034 | B32: Portland | C32: 2026-08-09 PM | D32: 2026-08-09 16:22 | E32: 2026-08-09 17:00 | F32: 1
A33: SHP-60035 | B33: Portland | C33: 2026-08-07 AM | D33: 2026-08-07 11:07 | E33: 2026-08-07 12:00 | F33: 1
A34: SHP-60036 | B34: Portland | C34: 2026-08-13 08:00-10:00 | D34: 2026-08-13 08:10 | E34: 2026-08-13 10:00 | F34: 1
A35: SHP-60037 | B35: Portland | C35: 2026-08-13 AM | D35: 2026-08-13 12:37 | E35: 2026-08-13 12:00 | F35: 0 | G35: Address
A36: SHP-60038 | B36: Portland | C36: 2026-08-11 AM | D36: 2026-08-11 09:34 | E36: 2026-08-11 12:00 | F36: 1
A37: SHP-60039 | B37: Portland | C37: 2026-08-12 All day | D37: 2026-08-12 16:26 | E37: 2026-08-12 17:00 | F37: 1
A38: SHP-60040 | B38: Portland | C38: 2026-08-07 All day | D38: 2026-08-07 17:48 | E38: 2026-08-07 17:00 | F38: 0 | G38: Weather
A39: SHP-60041 | B39: Portland | C39: 2026-08-26 13:00-15:00 | D39: 2026-08-26 15:14 | E39: 2026-08-26 15:00 | F39: 0 | G39: Mechanical
A40: SHP-60042 | B40: Portland | C40: 2026-08-08 08:00-10:00 | D40: 2026-08-08 08:26 | E40: 2026-08-08 10:00 | F40: 1
...

Sheet Report
A1: Hub | B1: Shipments delivered | C1: On time | D1: Late | E1: On-time %
A2: Portland | B2: =COUNTIF(Data!$B$2:$B$341,$A2) | C2: =SUMIF(Data!$B$2:$B$341,$A2,Data!$F$2:$F$341) | D2: =B2-C2 | E2: =IF(B2=0,"n/a",ROUND(C2/B2,4))
A3: Denver | B3: =COUNTIF(Data!$B$2:$B$341,$A3) | C3: =SUMIF(Data!$B$2:$B$341,$A3,Data!$F$2:$F$341) | D3: =B3-C3 | E3: =IF(B3=0,"n/a",ROUND(C3/B3,4))
A4: Austin | B4: =COUNTIF(Data!$B$2:$B$341,$A4) | C4: =SUMIF(Data!$B$2:$B$341,$A4,Data!$F$2:$F$341) | D4: =B4-C4 | E4: =IF(B4=0,"n/a",ROUND(C4/B4,4))
A5: Total - all hubs | B5: =SUM(B2:B4) | C5: =SUM(C2:C4) | D5: =SUM(D2:D4) | E5: =IF(B5=0,"n/a",ROUND(C5/B5,4))
A7: Why the late ones were late | B7: Shipments
A8: Weather | B8: =COUNTIF(Data!$G$2:$G$341,$A8)
A9: Mechanical | B9: =COUNTIF(Data!$G$2:$G$341,$A9)
A10: Customer | B10: =COUNTIF(Data!$G$2:$G$341,$A10)
A11: Address | B11: =COUNTIF(Data!$G$2:$G$341,$A11)
A12: Route volume | B12: =COUNTIF(Data!$G$2:$G$341,$A12)
A13: Not recorded | B13: =COUNTIF(Data!$G$2:$G$341,$A13)
A14: Total late | B14: =SUM(B8:B13)
A16: On time means the last piece of the shipment landed inside the promised window, in hub local time. Attempted, refused and cancelled stops are not deliveries.
