Workbook

Sheet Summary
A1: Grant | B1: Line code | C1: Budget line | D1: Budget | E1: Allowable spent to date | F1: Remaining | G1: Disallowed
A2: State Clean Water Fund - Mill Creek Restoration | B2: SCWF-PER | C2: Restoration personnel | D2: 38000 | E2: =SUMIFS(Detail!$H$2:$H$67,Detail!$F$2:$F$67,B2,Detail!$I$2:$I$67,"Yes") | F2: =D2-E2 | G2: =SUMIFS(Detail!$H$2:$H$67,Detail!$F$2:$F$67,B2,Detail!$I$2:$I$67,"No")
A3: State Clean Water Fund - Mill Creek Restoration | B3: SCWF-CON | C3: Earthwork contractor | D3: 52000 | E3: =SUMIFS(Detail!$H$2:$H$67,Detail!$F$2:$F$67,B3,Detail!$I$2:$I$67,"Yes") | F3: =D3-E3 | G3: =SUMIFS(Detail!$H$2:$H$67,Detail!$F$2:$F$67,B3,Detail!$I$2:$I$67,"No")
A4: State Clean Water Fund - Mill Creek Restoration | B4: SCWF-MAT | C4: Restoration materials | D4: 18500 | E4: =SUMIFS(Detail!$H$2:$H$67,Detail!$F$2:$F$67,B4,Detail!$I$2:$I$67,"Yes") | F4: =D4-E4 | G4: =SUMIFS(Detail!$H$2:$H$67,Detail!$F$2:$F$67,B4,Detail!$I$2:$I$67,"No")
A5: State Clean Water Fund - Mill Creek Restoration | B5: SCWF-MIL | C5: Field mileage | D5: 2400 | E5: =SUMIFS(Detail!$H$2:$H$67,Detail!$F$2:$F$67,B5,Detail!$I$2:$I$67,"Yes") | F5: =D5-E5 | G5: =SUMIFS(Detail!$H$2:$H$67,Detail!$F$2:$F$67,B5,Detail!$I$2:$I$67,"No")
A6: Hartwell Family Foundation - Watershed Classrooms | B6: HFF-EDU | C6: Education staff | D6: 24000 | E6: =SUMIFS(Detail!$H$2:$H$67,Detail!$F$2:$F$67,B6,Detail!$I$2:$I$67,"Yes") | F6: =D6-E6 | G6: =SUMIFS(Detail!$H$2:$H$67,Detail!$F$2:$F$67,B6,Detail!$I$2:$I$67,"No")
A7: Hartwell Family Foundation - Watershed Classrooms | B7: HFF-SUP | C7: Classroom kits | D7: 6200 | E7: =SUMIFS(Detail!$H$2:$H$67,Detail!$F$2:$F$67,B7,Detail!$I$2:$I$67,"Yes") | F7: =D7-E7 | G7: =SUMIFS(Detail!$H$2:$H$67,Detail!$F$2:$F$67,B7,Detail!$I$2:$I$67,"No")
A8: Hartwell Family Foundation - Watershed Classrooms | B8: HFF-BUS | C8: Student buses | D8: 4800 | E8: =SUMIFS(Detail!$H$2:$H$67,Detail!$F$2:$F$67,B8,Detail!$I$2:$I$67,"Yes") | F8: =D8-E8 | G8: =SUMIFS(Detail!$H$2:$H$67,Detail!$F$2:$F$67,B8,Detail!$I$2:$I$67,"No")
A9: Hartwell Family Foundation - Watershed Classrooms | B9: HFF-PRT | C9: Curriculum printing | D9: 2100 | E9: =SUMIFS(Detail!$H$2:$H$67,Detail!$F$2:$F$67,B9,Detail!$I$2:$I$67,"Yes") | F9: =D9-E9 | G9: =SUMIFS(Detail!$H$2:$H$67,Detail!$F$2:$F$67,B9,Detail!$I$2:$I$67,"No")
A10: County Parks Community Grant - Volunteer Stream Monitoring | B10: CPCG-STI | C10: Coordinator stipend | D10: 9000 | E10: =SUMIFS(Detail!$H$2:$H$67,Detail!$F$2:$F$67,B10,Detail!$I$2:$I$67,"Yes") | F10: =D10-E10 | G10: =SUMIFS(Detail!$H$2:$H$67,Detail!$F$2:$F$67,B10,Detail!$I$2:$I$67,"No")
A11: County Parks Community Grant - Volunteer Stream Monitoring | B11: CPCG-EQP | C11: Monitoring equipment | D11: 5400 | E11: =SUMIFS(Detail!$H$2:$H$67,Detail!$F$2:$F$67,B11,Detail!$I$2:$I$67,"Yes") | F11: =D11-E11 | G11: =SUMIFS(Detail!$H$2:$H$67,Detail!$F$2:$F$67,B11,Detail!$I$2:$I$67,"No")
A12: County Parks Community Grant - Volunteer Stream Monitoring | B12: CPCG-VOL | C12: Volunteer recognition | D12: 1500 | E12: =SUMIFS(Detail!$H$2:$H$67,Detail!$F$2:$F$67,B12,Detail!$I$2:$I$67,"Yes") | F12: =D12-E12 | G12: =SUMIFS(Detail!$H$2:$H$67,Detail!$F$2:$F$67,B12,Detail!$I$2:$I$67,"No")
A13: County Parks Community Grant - Volunteer Stream Monitoring | B13: CPCG-OUT | C13: Outreach printing | D13: 1200 | E13: =SUMIFS(Detail!$H$2:$H$67,Detail!$F$2:$F$67,B13,Detail!$I$2:$I$67,"Yes") | F13: =D13-E13 | G13: =SUMIFS(Detail!$H$2:$H$67,Detail!$F$2:$F$67,B13,Detail!$I$2:$I$67,"No")
A14: Total all grants | D14: =SUM(D2:D13) | E14: =SUM(E2:E13) | F14: =SUM(F2:F13) | G14: =SUM(G2:G13)

Sheet Detail
A1: Entry | B1: Posted | C1: Vendor | D1: Description | E1: Expense amount | F1: Line code | G1: Share | H1: Charged amount | I1: Allowable | J1: Why not
A2: JE-2276 | B2: 46050 | C2: Payroll - Gusto | D2: Restoration crew lead wages | E2: 3288.39 | F2: SCWF-PER | G2: 1 | H2: 3288.39 | I2: Yes
A3: JE-2284 | B3: 46080 | C3: Payroll - Gusto | D3: Restoration crew lead wages | E3: 3142.45 | F3: SCWF-PER | G3: 1 | H3: 3142.45 | I3: Yes
A4: JE-2282 | B4: 46080 | C4: Payroll - Gusto | D4: Education specialist wages | E4: 1842.94 | F4: HFF-EDU | G4: 1 | H4: 1842.94 | I4: Yes
A5: JE-2302 | B5: 46109 | C5: Payroll - Gusto | D5: Restoration crew lead wages | E5: 3207.51 | F5: SCWF-PER | G5: 1 | H5: 3207.51 | I5: Yes
A6: JE-2305 | B6: 46109 | C6: Payroll - Gusto | D6: Program coordinator wages (split) | E6: 3461.09 | F6: SCWF-PER | G6: 0.6 | H6: 2076.65 | I6: Yes
A7: JE-2305 | B7: 46109 | C7: Payroll - Gusto | D7: Program coordinator wages (split) | E7: 3461.09 | F7: CPCG-STI | G7: 0.4 | H7: 1384.44 | I7: Yes
A8: JE-2300 | B8: 46109 | C8: Payroll - Gusto | D8: Education specialist wages | E8: 2108.19 | F8: HFF-EDU | G8: 1 | H8: 2108.19 | I8: Yes
A9: JE-2331 | B9: 46140 | C9: Payroll - Gusto | D9: Restoration crew lead wages | E9: 3160.26 | F9: SCWF-PER | G9: 1 | H9: 3160.26 | I9: Yes
A10: JE-2335 | B10: 46140 | C10: Payroll - Gusto | D10: Program coordinator wages (split) | E10: 3252.12 | F10: SCWF-PER | G10: 0.6 | H10: 1951.27 | I10: Yes
A11: JE-2335 | B11: 46140 | C11: Payroll - Gusto | D11: Program coordinator wages (split) | E11: 3252.12 | F11: CPCG-STI | G11: 0.4 | H11: 1300.85 | I11: Yes
A12: JE-2328 | B12: 46140 | C12: Payroll - Gusto | D12: Education specialist wages | E12: 1809.92 | F12: HFF-EDU | G12: 1 | H12: 1809.92 | I12: Yes
A13: JE-2353 | B13: 46170 | C13: Payroll - Gusto | D13: Restoration crew lead wages | E13: 3004.46 | F13: SCWF-PER | G13: 1 | H13: 3004.46 | I13: Yes
... A35: JE-2293 | B35: 46092 | C35: Erosion Supply Co | D35: Rock for toe protection | E35: 952.75 | F35: SCWF-MAT | G35: 1 | H35: 952.75 | I35: Yes
A36: JE-2272 | B36: 46034 | C36: Prairie Moon Nursery | D36: Bare-root order (December invoice) | E36: 1255.86 | F36: SCWF-MAT | G36: 1 | H36: 1255.86 | I36: No | J36: incurred before the award period
A37: JE-2318 | B37: 46125 | C37: Mill Street Pizza | D37: Pizza and drinks - restoration volunteer planting day | E37: 221.89 | F37: SCWF-MAT | G37: 1 | H37: 221.89 | I37: No | J37: food is not allowable on the state fund
A38: JE-2291 | B38: 46088 | C38: Staff mileage reimbursement | D38: Field mileage - site visits | E38: 254.32 | F38: SCWF-MIL | G38: 1 | H38: 254.32 | I38: Yes
A39: JE-2309 | B39: 46119 | C39: Staff mileage reimbursement | D39: Field mileage - site visits | E39: 148.65 | F39: SCWF-MIL | G39: 1 | H39: 148.65 | I39: Yes
A40: JE-2338 | B40: 46147 | C40: Staff mileage reimbursement | D40: Field mileage - site visits | E40: 111.18 | F40: SCWF-MIL | G40: 1 | H40: 111.18 | I40: Yes
A41: JE-2364 | B41: 46176 | C41: Staff mileage reimbursement | D41: Field mileage - site visits | E41: 208.26 | F41: SCWF-MIL | G41: 1 | H41: 208.26 | I41: Yes
A42: JE-2386 | B42: 46207 | C42: Staff mileage reimbursement | D42: Field mileage - site visits | E42: 176.83 | F42: SCWF-MIL | G42: 1 | H42: 176.83 | I42: Yes
A43: JE-2401 | B43: 46241 | C43: Staff mileage reimbursement | D43: Field mileage - site visits | E43: 153.15 | F43: SCWF-MIL | G43: 1 | H43: 153.15 | I43: Yes
A44: JE-2324 | B44: 46134 | C44: Staff mileage reimbursement | D44: Mileage - school visits | E44: 265.67 | F44: HFF-EDU | G44: 1 | H44: 265.67 | I44: No | J44: the foundation does not pay staff mileage
A45: JE-2388 | B45: 46214 | C45: Staff mileage reimbursement | D45: Mileage - teacher workshop | E45: 120.94 | F45: HFF-EDU | G45: 1 | H45: 120.94 | I45: No | J45: the foundation does not pay staff mileage
A46: JE-2377 | B46: 46196 | C46: Carolina Biological | D46: Macroinvertebrate classroom kits | E46: 1106.19 | F46: HFF-SUP | G46: 1 | H46: 1106.19 | I46: Yes
A47: JE-2374 | B47: 46192 | C47: Carolina Biological | D47: Macroinvertebrate classroom kits | E47: 955.59 | F47: HFF-SUP | G47: 1 | H47: 955.59 | I47: Yes
A48: JE-2390 | B48: 46225 | C48: Carolina Biological | D48: Macroinvertebrate classroom kits | E48: 911.47 | F48: HFF-SUP | G48: 1 | H48: 911.47 | I48: Yes
A49: JE-2308 | B49: 46115 | C49: Blue Bird Charter Lines | D49: Field trip buses | E49: 861.52 | F49: HFF-BUS | G49: 1 | H49: 861.52 | I49: Yes
A50: JE-2314 | B50: 46125 | C50: Blue Bird Charter Lines | D50: Field trip buses | E50: 527.5 | F50: HFF-BUS | G50: 1 | H50: 527.5 | I50: Yes
A51: JE-2342 | B51: 46156 | C51: Blue Bird Charter Lines | D51: Field trip buses | E51: 726.35 | F51: HFF-BUS | G51: 1 | H51: 726.35 | I51: Yes
A52: JE-2288 | B52: 46087 | C52: Quill & Ink Print Shop | D52: Student field guides | E52: 1086.14 | F52: HFF-PRT | G52: 1 | H52: 1086.14 | I52: Yes
A53: JE-2295 | B53: 46101 | C53: LaMotte Company | D53: Water test kits and reagents | E53: 1235.74 | F53: CPCG-EQP | G53: 1 | H53: 1235.74 | I53: Yes
A54: JE-2360 | B54: 46176 | C54: LaMotte Company | D54: Water test kits and reagents | E54: 1262.12 | F54: CPCG-EQP | G54: 1 | H54: 1262.12 | I54: Yes
A55: JE-2367 | B55: 46183 | C55: LaMotte Company | D55: Credit memo - returned damaged reagent case | E55: -300.91 | F55: CPCG-EQP | G55: 1 | H55: -300.91 | I55: Yes
A56: JE-2356 | B56: 46174 | C56: Riverside Deli | D56: Volunteer lunch - joint planting and monitoring day | E56: 359.91 | F56: SCWF-MAT | G56: 0.5 | H56: 179.96 | I56: No | J56: food is not allowable on the state fund
A57: JE-2356 | B57: 46174 | C57: Riverside Deli | D57: Volunteer lunch - joint planting and monitoring day | E57: 359.91 | F57: CPCG-VOL | G57: 0.5 | H57: 179.95 | I57: Yes
A58: JE-2400 | B58: 46232 | C58: Target | D58: Gift cards - top volunteer monitors | E58: 241.14 | F58: CPCG-VOL | G58: 1 | H58: 241.14 | I58: No | J58: gift cards are not allowable on the county grant
A59: JE-2403 | B59: 46246 | C59: Vintner's Cellar | D59: Wine for volunteer appreciation dinner | E59: 138.55 | F59: CPCG-VOL | G59: 1 | H59: 138.55 | I59: No | J59: alcohol is not allowable on the county grant
A60: JE-2384 | B60: 46206 | C60: Grocery Outlet | D60: Snacks and water - volunteer monitoring training | E60: 55.17 | F60: CPCG-VOL | G60: 1 | H60: 55.17 | I60: Yes
A61: JE-2371 | B61: 46189 | C61: Grocery Outlet | D61: Snacks and water - volunteer monitoring training | E61: 70.89 | F61: CPCG-VOL | G61: 1 | H61: 70.89 | I61: Yes
...
